Workbook

Sheet Podsumowanie
A1: Siz3r — porównanie pomiarów ciała
A2: 12 plików • 4 osoby • 1 i 2 zdjęcia • wszystkie wartości w cm
A3: Średnia pomyłka: o ile cm wynik odbiega od rzeczywistego pomiaru, niezależnie od tego, czy jest większy, czy mniejszy.
A4: Zawyżenie / zaniżenie: + oznacza wynik za duży, − za mały. Zawyżenia i zaniżenia mogą się znosić w średniej.
A5: Co daje 2. zdjęcie? „Lepiej” oznacza mniejszą średnią pomyłkę, a „gorzej” większą. Każda próba ma jednakową wagę.
A7: Mierzony wymiar | B7: Średnio o ile Siz3r się myli [cm] 1 zdjęcie | C7: Średnio o ile Siz3r się myli [cm] 2 zdjęcia | D7: Co daje 2. zdjęcie? Lepiej / gorzej | E7: Średnie zawyżenie lub zaniżenie [cm] 1 zdjęcie | F7: Średnie zawyżenie lub zaniżenie [cm] 2 zdjęcia | G7: Który wariant jest dokładniejszy?
A8: Wzrost | B8: =AVERAGEIFS('Dane źródłowe'!$I$2:$I$253,'Dane źródłowe'!$D$2:$D$253,1,'Dane źródłowe'!$E$2:$E$253,A8) -> 0 | C8: =AVERAGEIFS('Dane źródłowe'!$I$2:$I$253,'Dane źródłowe'!$D$2:$D$253,2,'Dane źródłowe'!$E$2:$E$253,A8) -> 0 | D8: =C8-B8 -> 0 | E8: =AVERAGEIFS('Dane źródłowe'!$H$2:$H$253,'Dane źródłowe'!$D$2:$D$253,1,'Dane źródłowe'!$E$2:$E$253,A8) -> 0 | F8: =AVERAGEIFS('Dane źródłowe'!$H$2:$H$253,'Dane źródłowe'!$D$2:$D$253,2,'Dane źródłowe'!$E$2:$E$253,A8) -> 0 | G8: =IF(B8<C8,"1 zdjęcie",IF(C8<B8,"2 zdjęcia","Tak samo")) -> Tak samo
A9: Obwód szyi | B9: =AVERAGEIFS('Dane źródłowe'!$I$2:$I$253,'Dane źródłowe'!$D$2:$D$253,1,'Dane źródłowe'!$E$2:$E$253,A9) -> 4.3333333 | C9: =AVERAGEIFS('Dane źródłowe'!$I$2:$I$253,'Dane źródłowe'!$D$2:$D$253,2,'Dane źródłowe'!$E$2:$E$253,A9) -> 3.3333333 | D9: =C9-B9 -> -1 | E9: =AVERAGEIFS('Dane źródłowe'!$H$2:$H$253,'Dane źródłowe'!$D$2:$D$253,1,'Dane źródłowe'!$E$2:$E$253,A9) -> 4.1666667 | F9: =AVERAGEIFS('Dane źródłowe'!$H$2:$H$253,'Dane źródłowe'!$D$2:$D$253,2,'Dane źródłowe'!$E$2:$E$253,A9) -> 3 | G9: =IF(B9<C9,"1 zdjęcie",IF(C9<B9,"2 zdjęcia","Tak samo")) -> 2 zdjęcia
A10: Szerokość ramion | B10: =AVERAGEIFS('Dane źródłowe'!$I$2:$I$253,'Dane źródłowe'!$D$2:$D$253,1,'Dane źródłowe'!$E$2:$E$253,A10) -> 1.75 | C10: =AVERAGEIFS('Dane źródłowe'!$I$2:$I$253,'Dane źródłowe'!$D$2:$D$253,2,'Dane źródłowe'!$E$2:$E$253,A10) -> 1.75 | D10: =C10-B10 -> 0 | E10: =AVERAGEIFS('Dane źródłowe'!$H$2:$H$253,'Dane źródłowe'!$D$2:$D$253,1,'Dane źródłowe'!$E$2:$E$253,A10) -> 1.75 | F10: =AVERAGEIFS('Dane źródłowe'!$H$2:$H$253,'Dane źródłowe'!$D$2:$D$253,2,'Dane źródłowe'!$E$2:$E$253,A10) -> 0.25 | G10: =IF(B10<C10,"1 zdjęcie",IF(C10<B10,"2 zdjęcia","Tak samo")) -> Tak samo
A11: Obwód klatki piersiowej | B11: =AVERAGEIFS('Dane źródłowe'!$I$2:$I$253,'Dane źródłowe'!$D$2:$D$253,1,'Dane źródłowe'!$E$2:$E$253,A11) -> 4.5 | C11: =AVERAGEIFS('Dane źródłowe'!$I$2:$I$253,'Dane źródłowe'!$D$2:$D$253,2,'Dane źródłowe'!$E$2:$E$253,A11) -> 5.3333333 | D11: =C11-B11 -> 0.83333333 | E11: =AVERAGEIFS('Dane źródłowe'!$H$2:$H$253,'Dane źródłowe'!$D$2:$D$253,1,'Dane źródłowe'!$E$2:$E$253,A11) -> -0.5 | F11: =AVERAGEIFS('Dane źródłowe'!$H$2:$H$253,'Dane źródłowe'!$D$2:$D$253,2,'Dane źródłowe'!$E$2:$E$253,A11) -> 0.66666667 | G11: =IF(B11<C11,"1 zdjęcie",IF(C11<B11,"2 zdjęcia","Tak samo")) -> 1 zdjęcie
A12: Obwód biustu | B12: =AVERAGEIFS('Dane źródłowe'!$I$2:$I$253,'Dane źródłowe'!$D$2:$D$253,1,'Dane źródłowe'!$E$2:$E$253,A12) -> 4.6666667 | C12: =AVERAGEIFS('Dane źródłowe'!$I$2:$I$253,'Dane źródłowe'!$D$2:$D$253,2,'Dane źródłowe'!$E$2:$E$253,A12) -> 5.5 | D12: =C12-B12 -> 0.83333333 | E12: =AVERAGEIFS('Dane źródłowe'!$H$2:$H$253,'Dane źródłowe'!$D$2:$D$253,1,'Dane źródłowe'!$E$2:$E$253,A12) -> -0.33333333 | F12: =AVERAGEIFS('Dane źródłowe'!$H$2:$H$253,'Dane źródłowe'!$D$2:$D$253,2,'Dane źródłowe'!$E$2:$E$253,A12) -> 0.83333333 | G12: =IF(B12<C12,"1 zdjęcie",IF(C12<B12,"2 zdjęcia","Tak samo")) -> 1 zdjęcie
A13: Obwód pod biustem | B13: =AVERAGEIFS('Dane źródłowe'!$I$2:$I$253,'Dane źródłowe'!$D$2:$D$253,1,'Dane źródłowe'!$E$2:$E$253,A13) -> 5.5 | C13: =AVERAGEIFS('Dane źródłowe'!$I$2:$I$253,'Dane źródłowe'!$D$2:$D$253,2,'Dane źródłowe'!$E$2:$E$253,A13) -> 5.1666667 | D13: =C13-B13 -> -0.33333333 | E13: =AVERAGEIFS('Dane źródłowe'!$H$2:$H$253,'Dane źródłowe'!$D$2:$D$253,1,'Dane źródłowe'!$E$2:$E$253,A13) -> 2.8333333 | F13: =AVERAGEIFS('Dane źródłowe'!$H$2:$H$253,'Dane źródłowe'!$D$2:$D$253,2,'Dane źródłowe'!$E$2:$E$253,A13) -> 3.5 | G13: =IF(B13<C13,"1 zdjęcie",IF(C13<B13,"2 zdjęcia","Tak samo")) -> 2 zdjęcia
A14: Długość ramienia | B14: =AVERAGEIFS('Dane źródłowe'!$I$2:$I$253,'Dane źródłowe'!$D$2:$D$253,1,'Dane źródłowe'!$E$2:$E$253,A14) -> 1 | C14: =AVERAGEIFS('Dane źródłowe'!$I$2:$I$253,'Dane źródłowe'!$D$2:$D$253,2,'Dane źródłowe'!$E$2:$E$253,A14) -> 3.75 | D14: =C14-B14 -> 2.75 | E14: =AVERAGEIFS('Dane źródłowe'!$H$2:$H$253,'Dane źródłowe'!$D$2:$D$253,1,'Dane źródłowe'!$E$2:$E$253,A14) -> 1 | F14: =AVERAGEIFS('Dane źródłowe'!$H$2:$H$253,'Dane źródłowe'!$D$2:$D$253,2,'Dane źródłowe'!$E$2:$E$253,A14) -> 3.25 | G14: =IF(B14<C14,"1 zdjęcie",IF(C14<B14,"2 zdjęcia","Tak samo")) -> 1 zdjęcie
A15: Obwód ramienia | B15: =AVERAGEIFS('Dane źródłowe'!$I$2:$I$253,'Dane źródłowe'!$D$2:$D$253,1,'Dane źródłowe'!$E$2:$E$253,A15) -> 6.1666667 | C15: =AVERAGEIFS('Dane źródłowe'!$I$2:$I$253,'Dane źródłowe'!$D$2:$D$253,2,'Dane źródłowe'!$E$2:$E$253,A15) -> 1.6666667 | D15: =C15-B15 -> -4.5 | E15: =AVERAGEIFS('Dane źródłowe'!$H$2:$H$253,'Dane źródłowe'!$D$2:$D$253,1,'Dane źródłowe'!$E$2:$E$253,A15) -> -4.5 | F15: =AVERAGEIFS('Dane źródłowe'!$H$2:$H$253,'Dane źródłowe'!$D$2:$D$253,2,'Dane źródłowe'!$E$2:$E$253,A15) -> 0.33333333 | G15: =IF(B15<C15,"1 zdjęcie",IF(C15<B15,"2 zdjęcia","Tak samo")) -> 2 zdjęcia
A16: Obwód nadgarstka | B16: =AVERAGEIFS('Dane źródłowe'!$I$2:$I$253,'Dane źródłowe'!$D$2:$D$253,1,'Dane źródłowe'!$E$2:$E$253,A16) -> 2.3333333 | C16: =AVERAGEIFS('Dane źródłowe'!$I$2:$I$253,'Dane źródłowe'!$D$2:$D$253,2,'Dane źródłowe'!$E$2:$E$253,A16) -> 3.6666667 | D16: =C16-B16 -> 1.3333333 | E16: =AVERAGEIFS('Dane źródłowe'!$H$2:$H$253,'Dane źródłowe'!$D$2:$D$253,1,'Dane źródłowe'!$E$2:$E$253,A16) -> -1.3333333 | F16: =AVERAGEIFS('Dane źródłowe'!$H$2:$H$253,'Dane źródłowe'!$D$2:$D$253,2,'Dane źródłowe'!$E$2:$E$253,A16) -> 3.6666667 | G16: =IF(B16<C16,"1 zdjęcie",IF(C16<B16,"2 zdjęcia","Tak samo")) -> 1 zdjęcie
A17: Długość tułowia | B17: =AVERAGEIFS('Dane źródłowe'!$I$2:$I$253,'Dane źródłowe'!$D$2:$D$253,1,'Dane źródłowe'!$E$2:$E$253,A17) -> 21 | C17: =AVERAGEIFS('Dane źródłowe'!$I$2:$I$253,'Dane źródłowe'!$D$2:$D$253,2,'Dane źródłowe'!$E$2:$E$253,A17) -> 20.333333 | D17: =C17-B17 -> -0.66666667 | E17: =AVERAGEIFS('Dane źródłowe'!$H$2:$H$253,'Dane źródłowe'!$D$2:$D$253,1,'Dane źródłowe'!$E$2:$E$253,A17) -> 21 | F17: =AVERAGEIFS('Dane źródłowe'!$H$2:$H$253,'Dane źródłowe'!$D$2:$D$253,2,'Dane źródłowe'!$E$2:$E$253,A17) -> 20.333333 | G17: =IF(B17<C17,"1 zdjęcie",IF(C17<B17,"2 zdjęcia","Tak samo")) -> 2 zdjęcia
A18: Długość przodu | B18: =AVERAGEIFS('Dane źródłowe'!$I$2:$I$253,'Dane źródłowe'!$D$2:$D$253,1,'Dane źródłowe'!$E$2:$E$253,A18) -> 5 | C18: =AVERAGEIFS('Dane źródłowe'!$I$2:$I$253,'Dane źródłowe'!$D$2:$D$253,2,'Dane źródłowe'!$E$2:$E$253,A18) -> 5 | D18: =C18-B18 -> 0 | E18: =AVERAGEIFS('Dane źródłowe'!$H$2:$H$253,'Dane źródłowe'!$D$2:$D$253,1,'Dane źródłowe'!$E$2:$E$253,A18) -> 5 | F18: =AVERAGEIFS('Dane źródłowe'!$H$2:$H$253,'Dane źródłowe'!$D$2:$D$253,2,'Dane źródłowe'!$E$2:$E$253,A18) -> 5 | G18: =IF(B18<C18,"1 zdjęcie",IF(C18<B18,"2 zdjęcia","Tak samo")) -> Tak samo
A19: Długość pleców | B19: =AVERAGEIFS('Dane źródłowe'!$I$2:$I$253,'Dane źródłowe'!$D$2:$D$253,1,'Dane źródłowe'!$E$2:$E$253,A19) -> 1.5 | C19: =AVERAGEIFS('Dane źródłowe'!$I$2:$I$253,'Dane źródłowe'!$D$2:$D$253,2,'Dane źródłowe'!$E$2:$E$253,A19) -> 1.5 | D19: =C19-B19 -> 0 | E19: =AVERAGEIFS('Dane źródłowe'!$H$2:$H$253,'Dane źródłowe'!$D$2:$D$253,1,'Dane źródłowe'!$E$2:$E$253,A19) -> 1.5 | F19: =AVERAGEIFS('Dane źródłowe'!$H$2:$H$253,'Dane źródłowe'!$D$2:$D$253,2,'Dane źródłowe'!$E$2:$E$253,A19) -> 1.5 | G19: =IF(B19<C19,"1 zdjęcie",IF(C19<B19,"2 zdjęcia","Tak samo")) -> Tak samo
... A28: Obwód kostki | B28: =AVERAGEIFS('Dane źródłowe'!$I$2:$I$253,'Dane źródłowe'!$D$2:$D$253,1,'Dane źródłowe'!$E$2:$E$253,A28) -> 10.333333 | C28: =AVERAGEIFS('Dane źródłowe'!$I$2:$I$253,'Dane źródłowe'!$D$2:$D$253,2,'Dane źródłowe'!$E$2:$E$253,A28) -> 9.8333333 | D28: =C28-B28 -> -0.5 | E28: =AVERAGEIFS('Dane źródłowe'!$H$2:$H$253,'Dane źródłowe'!$D$2:$D$253,1,'Dane źródłowe'!$E$2:$E$253,A28) -> -0.66666667 | F28: =AVERAGEIFS('Dane źródłowe'!$H$2:$H$253,'Dane źródłowe'!$D$2:$D$253,2,'Dane źródłowe'!$E$2:$E$253,A28) -> 9.8333333 | G28: =IF(B28<C28,"1 zdjęcie",IF(C28<B28,"2 zdjęcia","Tak samo")) -> 2 zdjęcia
A30: Łącznie (dostępne pozycje) | B30: 8.7722772 | C30: 9.6633663 | D30: 0.89108911 | E30: 4.980198 | F30: 8.2376238 | G30: 1 zdjęcie
A31: Łączny wynik uśrednia 101 dostępnych pozycji na wariant; nie jest średnią z 21 średnich w tabeli.
A32: Plus w różnicy ze znakiem = zawyżenie, minus = zaniżenie. Pomiary klatki i biustu pozostawiono jako odrębne pozycje.

Sheet Osoby
A1: Osoba | B1: Liczba prób 1 zdjęcie | C1: Liczba prób 2 zdjęcia | D1: Średnio o ile Siz3r się myli [cm] 1 zdjęcie | E1: Średnio o ile Siz3r się myli [cm] 2 zdjęcia | F1: Co daje 2. zdjęcie? Lepiej / gorzej
A2: BB | B2: 1 | C2: 1 | D2: 5.8235294 | E2: 8.6470588 | F2: 2.8235294
A3: JB | B3: 2 | C3: 2 | D3: 11.166667 | E3: 11.642857 | F3: 0.47619048
A4: PF | B4: 2 | C4: 2 | D4: 6.9615385 | E4: 7.5769231 | F4: 0.61538462
A5: RF | B5: 1 | C5: 1 | D5: 8.5625 | E5: 8.9375 | F5: 0.375

Sheet Próby
A1: Plik | B1: Osoba | C1: Liczba zdjęć | D1: Numer próby | E1: Brakujące rzeczywiste pomiary | F1: Średnio o ile Siz3r się myli [cm] | G1: Średnie zawyżenie lub zaniżenie [cm]
A2: BB-1photo-1.pdf | B2: BB | C2: 1 | D2: 1 | E2: 4 | F2: 5.8235294 | G2: 3.2352941
A3: BB-2photos-1.pdf | B3: BB | C3: 2 | D3: 1 | E3: 4 | F3: 8.6470588 | G3: 6.5294118
A4: JB-1photo-1.pdf | B4: JB | C4: 1 | D4: 1 | E4: 0 | F4: 10.5 | G4: 7.4047619
A5: JB-1photo-2.pdf | B5: JB | C5: 1 | D5: 2 | E5: 0 | F5: 11.833333 | G5: 7.3571429
A6: JB-2photos-1.pdf | B6: JB | C6: 2 | D6: 1 | E6: 0 | F6: 11.452381 | G6: 11.309524
A7: JB-2photos-2.pdf | B7: JB | C7: 2 | D7: 2 | E7: 0 | F7: 11.833333 | G7: 11.785714
A8: PF-1photo-1.pdf | B8: PF | C8: 1 | D8: 1 | E8: 8 | F8: 6.3846154 | G8: -1.6153846
A9: PF-1photo-2.pdf | B9: PF | C9: 1 | D9: 2 | E9: 8 | F9: 7.5384615 | G9: 4.3076923
A10: PF-2photos-1.pdf | B10: PF | C10: 2 | D10: 1 | E10: 8 | F10: 7.2307692 | G10: 3.0769231
A11: PF-2photos-2.pdf | B11: PF | C11: 2 | D11: 2 | E11: 8 | F11: 7.9230769 | G11: 6.3846154
A12: RF-1photo-1.pdf | B12: RF | C12: 1 | D12: 1 | E12: 5 | F12: 8.5625 | G12: 6.4375
A13: RF-2photos-1.pdf | B13: RF | C13: 2 | D13: 1 | E13: 5 | F13: 8.9375 | G13: 7.0625

Sheet Osoby i wymiary
A1: Osoba | B1: Mierzony wymiar | C1: Średnio o ile Siz3r się myli [cm] 1 zdjęcie | D1: Średnio o ile Siz3r się myli [cm] 2 zdjęcia | E1: Co daje 2. zdjęcie? Lepiej / gorzej | F1: Średnie zawyżenie lub zaniżenie [cm] 1 zdjęcie | G1: Średnie zawyżenie lub zaniżenie [cm] 2 zdjęcia
A2: BB | B2: Wzrost | C2: 0 | D2: 0 | E2: 0 | F2: 0 | G2: 0
A3: BB | B3: Obwód szyi | C3: 8 | D3: 7 | E3: -1 | F3: 8 | G3: 7
A4: BB | B4: Szerokość ramion | C4: 2 | D4: 1 | E4: -1 | F4: 2 | G4: 1
A5: BB | B5: Obwód klatki piersiowej | C5: 4 | D5: 7 | E5: 3 | F5: 4 | G5: 7
A6: BB | B6: Obwód biustu | C6: 4 | D6: 7 | E6: 3 | F6: 4 | G6: 7
A7: BB | B7: Obwód pod biustem | C7: 6 | D7: 8 | E7: 2 | F7: 6 | G7: 8
A8: BB | B8: Długość ramienia | C8: 1 | D8: 5 | E8: 4 | F8: 1 | G8: 5
A9: BB | B9: Obwód ramienia | C9: 5 | D9: 6 | E9: 1 | F9: 5 | G9: 6
A10: BB | B10: Obwód nadgarstka | C10: 4 | D10: 2 | E10: -2 | F10: -4 | G10: 2
A11: BB | B11: Długość tułowia
A12: BB | B12: Długość przodu
A13: BB | B13: Długość pleców
A14: BB | B14: Długość pleców do bioder
A15: BB | B15: Obwód talii | C15: 13 | D15: 23 | E15: 10 | F15: 13 | G15: 23
A16: BB | B16: Obwód bioder | C16: 11 | D16: 18 | E16: 7 | F16: 11 | G16: 18
A17: BB | B17: Wysokość stanu | C17: 11 | D17: 16 | E17: 5 | F17: 11 | G17: 16
A18: BB | B18: Obwód uda | C18: 4 | D18: 4 | E18: 0 | F18: 4 | G18: 4
A19: BB | B19: Długość nogawki po wewnętrznej | C19: 17 | D19: 18 | E19: 1 | F19: -17 | G19: -18
A20: BB | B20: Obwód kolana | C20: 1 | D20: 8 | E20: 7 | F20: -1 | G20: 8
A21: BB | B21: Obwód łydki | C21: 0 | D21: 4 | E21: 4 | F21: 0 | G21: 4
A22: BB | B22: Obwód kostki | C22: 8 | D22: 13 | E22: 5 | F22: 8 | G22: 13
A23: JB | B23: Wzrost | C23: 0 | D23: 0 | E23: 0 | F23: 0 | G23: 0
A24: JB | B24: Obwód szyi | C24: 0.5 | D24: 0.5 | E24: 0 | F24: 0 | G24: -0.5
A25: JB | B25: Szerokość ramion | C25: 2.5 | D25: 1.5 | E25: -1 | F25: 2.5 | G25: 1.5
A26: JB | B26: Obwód klatki piersiowej | C26: 4 | D26: 5 | E26: 1 | F26: 4 | G26: 5
... A45: PF | B45: Obwód szyi | C45: 5 | D45: 2.5 | E45: -2.5 | F45: 5 | G45: 2.5
A46: PF | B46: Szerokość ramion
A47: PF | B47: Obwód klatki piersiowej | C47: 7.5 | D47: 7 | E47: -0.5 | F47: -7.5 | G47: -7
A48: PF | B48: Obwód biustu | C48: 7.5 | D48: 7 | E48: -0.5 | F48: -7.5 | G48: -7
A49: PF | B49: Obwód pod biustem | C49: 5.5 | D49: 3 | E49: -2.5 | F49: -2.5 | G49: -2
A50: PF | B50: Długość ramienia
A51: PF | B51: Obwód ramienia | C51: 4 | D51: 0.5 | E51: -3.5 | F51: -4 | G51: -0.5
A52: PF | B52: Obwód nadgarstka | C52: 1.5 | D52: 5.5 | E52: 4 | F52: 1.5 | G52: 5.5
A53: PF | B53: Długość tułowia
A54: PF | B54: Długość przodu
A55: PF | B55: Długość pleców
A56: PF | B56: Długość pleców do bioder
A57: PF | B57: Obwód talii | C57: 11.5 | D57: 14.5 | E57: 3 | F57: 11.5 | G57: 14.5
A58: PF | B58: Obwód bioder | C58: 11.5 | D58: 10 | E58: -1.5 | F58: 11.5 | G58: 10
...

Sheet Równa waga osób
A1: Równa waga osób — wariant pomocniczy
A2: Najpierw średni błąd z prób jednej osoby, potem średnia z osób z dostępnym pomiarem. JB i PF nie mają większej wagi.
A3: Mierzony wymiar | B3: Liczba osób | C3: Średnio o ile Siz3r się myli [cm] 1 zdjęcie | D3: Średnio o ile Siz3r się myli [cm] 2 zdjęcia | E3: Co daje 2. zdjęcie? Lepiej / gorzej
A4: Wzrost | B4: 4 | C4: 0 | D4: 0 | E4: 0
A5: Obwód szyi | B5: 4 | C5: 5.125 | D5: 4.25 | E5: -0.875
A6: Szerokość ramion | B6: 3 | C6: 1.5 | D6: 1.8333333 | E6: 0.33333333
A7: Obwód klatki piersiowej | B7: 4 | C7: 3.875 | D7: 5 | E7: 1.125
A8: Obwód biustu | B8: 4 | C8: 4.125 | D8: 5.25 | E8: 1.125
A9: Obwód pod biustem | B9: 4 | C9: 5.375 | D9: 5.375 | E9: 0
A10: Długość ramienia | B10: 3 | C10: 0.83333333 | D10: 3.5 | E10: 2.6666667
A11: Obwód ramienia | B11: 4 | C11: 6.25 | D11: 2.25 | E11: -4
A12: Obwód nadgarstka | B12: 4 | C12: 2.25 | D12: 3.5 | E12: 1.25
A13: Długość tułowia | B13: 2 | C13: 19.5 | D13: 18.5 | E13: -1
A14: Długość przodu | B14: 1 | C14: 5 | D14: 5 | E14: 0
A15: Długość pleców | B15: 1 | C15: 1.5 | D15: 1.5 | E15: 0
... A24: Obwód kostki | B24: 4 | C24: 11.375 | D24: 12.25 | E24: 0.875

Sheet Dane źródłowe
A1: Plik | B1: Osoba | C1: Próba | D1: Liczba zdjęć | E1: Pomiar | F1: Siz3r [cm] | G1: Rzeczywisty [cm] | H1: Różnica [cm] | I1: Bezwzględna różnica [cm] | J1: Różnica w PDF [cm] | K1: Dostępność
A2: BB-1photo-1.pdf | B2: BB | C2: 1 | D2: 1 | E2: Wzrost | F2: 177 | G2: 177 | H2: =IF(G2="","",F2-G2) -> 0 | I2: =IF(H2="","",ABS(H2)) -> 0 | J2: 0 | K2: OK
A3: BB-1photo-1.pdf | B3: BB | C3: 1 | D3: 1 | E3: Obwód szyi | F3: 47 | G3: 39 | H3: =IF(G3="","",F3-G3) -> 8 | I3: =IF(H3="","",ABS(H3)) -> 8 | J3: 8 | K3: OK
A4: BB-1photo-1.pdf | B4: BB | C4: 1 | D4: 1 | E4: Szerokość ramion | F4: 46 | G4: 44 | H4: =IF(G4="","",F4-G4) -> 2 | I4: =IF(H4="","",ABS(H4)) -> 2 | J4: 2 | K4: OK
A5: BB-1photo-1.pdf | B5: BB | C5: 1 | D5: 1 | E5: Obwód klatki piersiowej | F5: 96 | G5: 92 | H5: =IF(G5="","",F5-G5) -> 4 | I5: =IF(H5="","",ABS(H5)) -> 4 | J5: 4 | K5: OK
A6: BB-1photo-1.pdf | B6: BB | C6: 1 | D6: 1 | E6: Obwód biustu | F6: 96 | G6: 92 | H6: =IF(G6="","",F6-G6) -> 4 | I6: =IF(H6="","",ABS(H6)) -> 4 | J6: 4 | K6: OK
A7: BB-1photo-1.pdf | B7: BB | C7: 1 | D7: 1 | E7: Obwód pod biustem | F7: 91 | G7: 85 | H7: =IF(G7="","",F7-G7) -> 6 | I7: =IF(H7="","",ABS(H7)) -> 6 | J7: 6 | K7: OK
A8: BB-1photo-1.pdf | B8: BB | C8: 1 | D8: 1 | E8: Długość ramienia | F8: 61 | G8: 60 | H8: =IF(G8="","",F8-G8) -> 1 | I8: =IF(H8="","",ABS(H8)) -> 1 | J8: 1 | K8: OK
A9: BB-1photo-1.pdf | B9: BB | C9: 1 | D9: 1 | E9: Obwód ramienia | F9: 34 | G9: 29 | H9: =IF(G9="","",F9-G9) -> 5 | I9: =IF(H9="","",ABS(H9)) -> 5 | J9: 5 | K9: OK
A10: BB-1photo-1.pdf | B10: BB | C10: 1 | D10: 1 | E10: Obwód nadgarstka | F10: 13 | G10: 17 | H10: =IF(G10="","",F10-G10) -> -4 | I10: =IF(H10="","",ABS(H10)) -> 4 | J10: -4 | K10: OK
A11: BB-1photo-1.pdf | B11: BB | C11: 1 | D11: 1 | E11: Długość tułowia | F11: 71 | H11: =IF(G11="","",F11-G11) | I11: =IF(H11="","",ABS(H11)) | K11: Brak rzeczywistego
A12: BB-1photo-1.pdf | B12: BB | C12: 1 | D12: 1 | E12: Długość przodu | F12: 61 | H12: =IF(G12="","",F12-G12) | I12: =IF(H12="","",ABS(H12)) | K12: Brak rzeczywistego
A13: BB-1photo-1.pdf | B13: BB | C13: 1 | D13: 1 | E13: Długość pleców | F13: 59 | H13: =IF(G13="","",F13-G13) | I13: =IF(H13="","",ABS(H13)) | K13: Brak rzeczywistego
A14: BB-1photo-1.pdf | B14: BB | C14: 1 | D14: 1 | E14: Długość pleców do bioder | F14: 71 | H14: =IF(G14="","",F14-G14) | I14: =IF(H14="","",ABS(H14)) | K14: Brak rzeczywistego
A15: BB-1photo-1.pdf | B15: BB | C15: 1 | D15: 1 | E15: Obwód talii | F15: 101 | G15: 88 | H15: =IF(G15="","",F15-G15) -> 13 | I15: =IF(H15="","",ABS(H15)) -> 13 | J15: 13 | K15: OK
A16: BB-1photo-1.pdf | B16: BB | C16: 1 | D16: 1 | E16: Obwód bioder | F16: 108 | G16: 97 | H16: =IF(G16="","",F16-G16) -> 11 | I16: =IF(H16="","",ABS(H16)) -> 11 | J16: 11 | K16: OK
A17: BB-1photo-1.pdf | B17: BB | C17: 1 | D17: 1 | E17: Wysokość stanu | F17: 84 | G17: 73 | H17: =IF(G17="","",F17-G17) -> 11 | I17: =IF(H17="","",ABS(H17)) -> 11 | J17: 11 | K17: OK
A18: BB-1photo-1.pdf | B18: BB | C18: 1 | D18: 1 | E18: Obwód uda | F18: 58 | G18: 54 | H18: =IF(G18="","",F18-G18) -> 4 | I18: =IF(H18="","",ABS(H18)) -> 4 | J18: 4 | K18: OK
A19: BB-1photo-1.pdf | B19: BB | C19: 1 | D19: 1 | E19: Długość nogawki po wewnętrznej | F19: 67 | G19: 84 | H19: =IF(G19="","",F19-G19) -> -17 | I19: =IF(H19="","",ABS(H19)) -> 17 | J19: -17 | K19: OK
A20: BB-1photo-1.pdf | B20: BB | C20: 1 | D20: 1 | E20: Obwód kolana | F20: 37 | G20: 38 | H20: =IF(G20="","",F20-G20) -> -1 | I20: =IF(H20="","",ABS(H20)) -> 1 | J20: -1 | K20: OK
A21: BB-1photo-1.pdf | B21: BB | C21: 1 | D21: 1 | E21: Obwód łydki | F21: 37 | G21: 37 | H21: =IF(G21="","",F21-G21) -> 0 | I21: =IF(H21="","",ABS(H21)) -> 0 | J21: 0 | K21: OK
A22: BB-1photo-1.pdf | B22: BB | C22: 1 | D22: 1 | E22: Obwód kostki | F22: 31 | G22: 23 | H22: =IF(G22="","",F22-G22) -> 8 | I22: =IF(H22="","",ABS(H22)) -> 8 | J22: 8 | K22: OK
A23: BB-2photos-1.pdf | B23: BB | C23: 1 | D23: 2 | E23: Wzrost | F23: 177 | G23: 177 | H23: =IF(G23="","",F23-G23) -> 0 | I23: =IF(H23="","",ABS(H23)) -> 0 | J23: 0 | K23: OK
A24: BB-2photos-1.pdf | B24: BB | C24: 1 | D24: 2 | E24: Obwód szyi | F24: 46 | G24: 39 | H24: =IF(G24="","",F24-G24) -> 7 | I24: =IF(H24="","",ABS(H24)) -> 7 | J24: 7 | K24: OK
A25: BB-2photos-1.pdf | B25: BB | C25: 1 | D25: 2 | E25: Szerokość ramion | F25: 45 | G25: 44 | H25: =IF(G25="","",F25-G25) -> 1 | I25: =IF(H25="","",ABS(H25)) -> 1 | J25: 1 | K25: OK
A26: BB-2photos-1.pdf | B26: BB | C26: 1 | D26: 2 | E26: Obwód klatki piersiowej | F26: 99 | G26: 92 | H26: =IF(G26="","",F26-G26) -> 7 | I26: =IF(H26="","",ABS(H26)) -> 7 | J26: 7 | K26: OK
... A31: BB-2photos-1.pdf | B31: BB | C31: 1 | D31: 2 | E31: Obwód nadgarstka | F31: 19 | G31: 17 | H31: =IF(G31="","",F31-G31) -> 2 | I31: =IF(H31="","",ABS(H31)) -> 2 | J31: 2 | K31: OK
A32: BB-2photos-1.pdf | B32: BB | C32: 1 | D32: 2 | E32: Długość tułowia | F32: 73 | H32: =IF(G32="","",F32-G32) | I32: =IF(H32="","",ABS(H32)) | K32: Brak rzeczywistego
A33: BB-2photos-1.pdf | B33: BB | C33: 1 | D33: 2 | E33: Długość przodu | F33: 63 | H33: =IF(G33="","",F33-G33) | I33: =IF(H33="","",ABS(H33)) | K33: Brak rzeczywistego
A34: BB-2photos-1.pdf | B34: BB | C34: 1 | D34: 2 | E34: Długość pleców | F34: 61 | H34: =IF(G34="","",F34-G34) | I34: =IF(H34="","",ABS(H34)) | K34: Brak rzeczywistego
A35: BB-2photos-1.pdf | B35: BB | C35: 1 | D35: 2 | E35: Długość pleców do bioder | F35: 73 | H35: =IF(G35="","",F35-G35) | I35: =IF(H35="","",ABS(H35)) | K35: Brak rzeczywistego
A36: BB-2photos-1.pdf | B36: BB | C36: 1 | D36: 2 | E36: Obwód talii | F36: 111 | G36: 88 | H36: =IF(G36="","",F36-G36) -> 23 | I36: =IF(H36="","",ABS(H36)) -> 23 | J36: 23 | K36: OK
A37: BB-2photos-1.pdf | B37: BB | C37: 1 | D37: 2 | E37: Obwód bioder | F37: 115 | G37: 97 | H37: =IF(G37="","",F37-G37) -> 18 | I37: =IF(H37="","",ABS(H37)) -> 18 | J37: 18 | K37: OK
A38: BB-2photos-1.pdf | B38: BB | C38: 1 | D38: 2 | E38: Wysokość stanu | F38: 89 | G38: 73 | H38: =IF(G38="","",F38-G38) -> 16 | I38: =IF(H38="","",ABS(H38)) -> 16 | J38: 16 | K38: OK
A39: BB-2photos-1.pdf | B39: BB | C39: 1 | D39: 2 | E39: Obwód uda | F39: 58 | G39: 54 | H39: =IF(G39="","",F39-G39) -> 4 | I39: =IF(H39="","",ABS(H39)) -> 4 | J39: 4 | K39: OK
A40: BB-2photos-1.pdf | B40: BB | C40: 1 | D40: 2 | E40: Długość nogawki po wewnętrznej | F40: 66 | G40: 84 | H40: =IF(G40="","",F40-G40) -> -18 | I40: =IF(H40="","",ABS(H40)) -> 18 | J40: -18 | K40: OK
A41: BB-2photos-1.pdf | B41: BB | C41: 1 | D41: 2 | E41: Obwód kolana | F41: 46 | G41: 38 | H41: =IF(G41="","",F41-G41) -> 8 | I41: =IF(H41="","",ABS(H41)) -> 8 | J41: 8 | K41: OK
A42: BB-2photos-1.pdf | B42: BB | C42: 1 | D42: 2 | E42: Obwód łydki | F42: 41 | G42: 37 | H42: =IF(G42="","",F42-G42) -> 4 | I42: =IF(H42="","",ABS(H42)) -> 4 | J42: 4 | K42: OK
A43: BB-2photos-1.pdf | B43: BB | C43: 1 | D43: 2 | E43: Obwód kostki | F43: 36 | G43: 23 | H43: =IF(G43="","",F43-G43) -> 13 | I43: =IF(H43="","",ABS(H43)) -> 13 | J43: 13 | K43: OK
A44: JB-1photo-1.pdf | B44: JB | C44: 1 | D44: 1 | E44: Wzrost | F44: 186 | G44: 186 | H44: =IF(G44="","",F44-G44) -> 0 | I44: =IF(H44="","",ABS(H44)) -> 0 | J44: 0 | K44: OK
...

Sheet Jak czytać
A1: Jak czytać raport
A2: Cel: średnie różnice Siz3r względem pomiarów rzeczywistych, osobno dla jednego i dwóch zdjęć.
A3: Nazwa JB-1photo-1: osoba JB, jedno zdjęcie, pierwsza próba. PF-2photos-2: osoba PF, dwa zdjęcia, druga próba.
A4: Liczbę zdjęć i próbę odczytano z nazw plików. Tytuły PDF typu „zdjęcie 3” nie określają liczby zdjęć wejściowych.
A5: Z 12 PDF odczytano 252 pozycje: 202 z pomiarem rzeczywistym i 50 bez niego. Po 101 porównań na wariant.
A6: Średnio o ile Siz3r się myli: średnia odległość wyniku od rzeczywistego pomiaru. Zawsze 0 lub więcej; mniej oznacza dokładniej.
A7: Przykład: wynik za duży o 4 cm i za mały o 4 cm dają średnią pomyłkę 4 cm, lecz średnie zawyżenie / zaniżenie 0 cm.
A8: Średnie zawyżenie / zaniżenie: średnia z Siz3r minus rzeczywisty. Plus oznacza wynik za duży, minus za mały.
A9: Co daje 2. zdjęcie: „1,00 cm lepiej” oznacza pomyłkę mniejszą o 1 cm, „1,00 cm gorzej” większą o 1 cm.
A10: Excel przechowuje efekt jako liczbę: wynik dla 2 zdjęć minus wynik dla 1 zdjęcia. Format komórki dodaje słowo „lepiej” lub „gorzej”.
A11: Główna tabela nadaje każdej próbie tę samą wagę. BB i RF mają po jednej próbie na wariant; JB i PF po dwie.
A12: Zakładka „Równa waga osób” pokazuje dodatkowy wariant, w którym najpierw uśredniono próby każdej osoby.
... A23: Źródłowe pliki pozostawiono bez zmian. Plik analiza.py umożliwia ponowne wygenerowanie raportu.

Sheet Pliki źródłowe
A1: Plik | B1: Osoba | C1: Liczba zdjęć | D1: Próba | E1: Liczba wierszy | F1: Strony | G1: SHA-256
A2: BB-1photo-1.pdf | B2: BB | C2: 1 | D2: 1 | E2: 21 | F2: 1 | G2: d6350421cb3338ce8ecb252a263379a5f8162b1284ef4cf251d7ab512d4a1210
A3: BB-2photos-1.pdf | B3: BB | C3: 2 | D3: 1 | E3: 21 | F3: 1 | G3: 2f36506a5147eeb2ca4df1ae929d3b89d582ff1e29f9d63e9aa55f6b9a9c0c3d
A4: JB-1photo-1.pdf | B4: JB | C4: 1 | D4: 1 | E4: 21 | F4: 1 | G4: 9fb0f53f56d89f3286cdc508b93c989ab8f24e241c305c500a1aeb32674efce1
A5: JB-1photo-2.pdf | B5: JB | C5: 1 | D5: 2 | E5: 21 | F5: 1 | G5: 2259c232b25da377958f7c7574d3b5a1f731611ef11e1d32ace566bd8b77c52e
A6: JB-2photos-1.pdf | B6: JB | C6: 2 | D6: 1 | E6: 21 | F6: 1 | G6: a5c661f972549b85b40f7819433df2b6d37a96aa46eaec603bdd1a1c86edeffb
A7: JB-2photos-2.pdf | B7: JB | C7: 2 | D7: 2 | E7: 21 | F7: 1 | G7: 16224c5c0202745c9046dc3eb2c15e08e1c90ab98db4239a3da614f4e15d9fd1
A8: PF-1photo-1.pdf | B8: PF | C8: 1 | D8: 1 | E8: 21 | F8: 1 | G8: 61180199f1bf866e1614379b2a0b8d785c27cd7104e20a8f57b0d699784eaf26
A9: PF-1photo-2.pdf | B9: PF | C9: 1 | D9: 2 | E9: 21 | F9: 1 | G9: 49f67bc9cf913446217fcb87755a12fc9152c9ac52ede0ef5aa6687b0195adf4
A10: PF-2photos-1.pdf | B10: PF | C10: 2 | D10: 1 | E10: 21 | F10: 1 | G10: 45f6b0609f398d0946bf3963cd2ee83bb0beb3b3d84b3a5e622ad91ce56bc096
A11: PF-2photos-2.pdf | B11: PF | C11: 2 | D11: 2 | E11: 21 | F11: 1 | G11: e24f5706f6a0bd00bbfe54d54a81efb233fee2186cf261670793780d1abc5f30
A12: RF-1photo-1.pdf | B12: RF | C12: 1 | D12: 1 | E12: 21 | F12: 1 | G12: 063ca8793f77a63b91c5d78169a45bafe5e0f5ebab245ecfa2193723b1d23e99
A13: RF-2photos-1.pdf | B13: RF | C13: 2 | D13: 1 | E13: 21 | F13: 1 | G13: e6b6e63fc9d902bbaef85a72831476b975a70e598960640e8725392ba9180c4e
